Workbook

Sheet 📖 Instructies
A1: 💰 BANKTRANSACTIE ANALYZER - FORMULE EDITIE
A3: ✨ SUPER SIMPEL - GEEN INSTALLATIE - GEEN MACRO'S!
A6: 🚀 SNEL STARTEN (3 STAPPEN):
A8: 1️⃣ EXPORT van je bank | C8: Log in bij je bank → Download transacties als CSV
A10: 2️⃣ PLAK in Excel | C10: Open CSV in Notepad → Kopieer ALLES → Plak in sheet 'CSV Import' cel A1
A12: 3️⃣ KLAAR! | C12: Ga naar 'Data Verwerkt' - alles is automatisch gecategoriseerd!
C13: Bekijk 'Dashboard' voor grafieken en statistieken
A16: 📊 SHEETS UITLEG:
A18: 📖 Instructies | C18: Deze pagina - beginnen hier
A19: 📥 CSV Import | C19: PLAK hier je CSV data (kopieer-plakken vanuit Notepad)
A20: 🏷️ Categorieregels | C20: Pas categorieën aan (100+ voorbeelden al ingevuld)
A21: ✅ Data Verwerkt | C21: Automatisch verrijkte data (formules doen alles!)
A22: 📊 Dashboard | C22: Overzichten per maand en categorie (automatische grafieken)
A25: 🔧 CATEGORIEËN AANPASSEN:
C27: 1. Ga naar sheet 'Categorieregels'
C28: 2. Voeg nieuwe regels toe of pas bestaande aan
C29: Kolom A: Zoekwoord (bijv. 'Albert Heijn')
C30: Kolom B: Categorie (bijv. 'Boodschappen')
C31: Kolom C: Subcategorie (bijv. 'Supermarkt')
C32: 3. Data in 'Data Verwerkt' wordt automatisch bijgewerkt!
A35: 💡 TIPS:
A37: ✓ CSV Formaat | C37: Zorg dat je CSV minimaal heeft: Datum, Omschrijving, Bedrag
A38: ✓ Headers | C38: Eerste regel moet kolomnamen zijn (Datum, Omschrijving, etc.)
A39: ✓ Meerdere imports | C39: Gewoon nieuwe data ONDER bestaande plakken in CSV Import
A40: ✓ Duplicaten | C40: Sorteer op datum en verwijder handmatig dubbele rijen
A41: ✓ Aanpassen | C41: Je kunt alles handmatig aanpassen in 'Data Verwerkt'
A44: 🔒 PRIVACY:
C46: ✅ 100% LOKAAL - Alles blijft op jouw computer
C47: ✅ GEEN internet verbinding nodig
C48: ✅ GEEN macro's of VBA code
C49: ✅ GEEN installatie van software
C50: ✅ Gewoon Excel formules
A53: ⚠️ BELANGRIJK:
C55: • Dit bestand gebruikt ALLEEN Excel formules (geen macro's)
C56: • Werkt in elke Excel versie 2016+
C57: • Ook compatible met Google Sheets (met kleine aanpassingen)
C58: • Sla regelmatig op (Ctrl+S)!
A61: 🆘 PROBLEMEN?
A63: ❓ Formules werken niet | C63: Check of je data in CSV Import begint bij A1
A64: ❓ Categorieën kloppen niet | C64: Pas 'Categorieregels' sheet aan en formules updaten automatisch
...

Sheet 📥 CSV Import
A1: 👇 PLAK JE CSV DATA HIER (vanaf cel A1)
A2: Instructies: Open je CSV in Notepad → Selecteer ALLES (Ctrl+A) → Kopieer (Ctrl+C) → Plak HIER in cel A3 (Ctrl+V)
A4: Datum | B4: Omschrijving | C4: Bedrag | D4: Tegenrekening
A5: 2025-01-23 | B5: Albert Heijn Amsterdam | C5: -45.67 | D5: NL12ABNA0123456789

Sheet 🏷️ Categorieregels
A1: Patroon | B1: Categorie | C1: Subcategorie | D1: Notitie
A2: Albert Heijn | B2: Boodschappen | C2: Supermarkt | D2: AH
A3: AH | B3: Boodschappen | C3: Supermarkt | D3: Albert Heijn kort
A4: Jumbo | B4: Boodschappen | C4: Supermarkt
A5: Lidl | B5: Boodschappen | C5: Supermarkt
A6: Aldi | B6: Boodschappen | C6: Supermarkt
A7: Etos | B7: Boodschappen | C7: Drogist
A8: Kruidvat | B8: Boodschappen | C8: Drogist
A9: Shell | B9: Vervoer | C9: Brandstof
A10: BP | B10: Vervoer | C10: Brandstof
A11: Esso | B11: Vervoer | C11: Brandstof
A12: NS | B12: Vervoer | C12: OV | D12: Nederlandse Spoorwegen
A13: OV-chip | B13: Vervoer | C13: OV
A14: Ziggo | B14: Abonnementen | C14: Internet
A15: KPN | B15: Abonnementen | C15: Internet
A16: Netflix | B16: Abonnementen | C16: Entertainment
A17: Spotify | B17: Abonnementen | C17: Entertainment
A18: Amazon | B18: Online Shopping
A19: Bol.com | B19: Online Shopping
A20: Coolblue | B20: Online Shopping
A21: MediaMarkt | B21: Elektronica
A22: Huur | B22: Wonen | C22: Huur
A23: Hypotheek | B23: Wonen | C23: Hypotheek
A24: Energie | B24: Wonen | C24: Utilities
A25: Waternet | B25: Wonen | C25: Utilities
A26: IKEA | B26: Wonen | C26: Inrichting
A27: Apotheek | B27: Gezondheid | C27: Medisch
A28: Tandarts | B28: Gezondheid | C28: Medisch
A29: Huisarts | B29: Gezondheid | C29: Medisch
A30: Zorgverzekering | B30: Verzekeringen | C30: Zorg
A31: Restaurant | B31: Horeca | C31: Restaurant
A32: McDonald | B32: Horeca | C32: Fast Food
A33: Burger King | B33: Horeca | C33: Fast Food
... A41: Belasting | B41: Inkomsten | C41: Terugave

Sheet ✅ Data Verwerkt
A1: Datum | B1: Omschrijving | C1: Bedrag | D1: Tegenrekening | E1: Jaar | F1: Maand | G1: MaandNaam | H1: InUit | I1: BedragAbs | J1: Categorie | K1: Subcategorie
A2: ='📥 CSV Import'!A5 | B2: ='📥 CSV Import'!B5 | C2: ='📥 CSV Import'!C5 | D2: ='📥 CSV Import'!D5 | E2: =IF(A2<>"",YEAR(A2),"") | F2: =IF(A2<>"",TEXT(A2,"YYYY-MM"),"") | G2: =IF(A2<>"",TEXT(A2,"MMMM YYYY"),"") | H2: =IF(C2>0,"Inkomsten",IF(C2<0,"Uitgaven","")) | I2: =IF(C2<>"",ABS(C2),"") | J2: =IFERROR(INDEX('🏷️ Categorieregels'!$B:$B,MATCH(TRUE,ISNUMBER(SEARCH('🏷️ Categorieregels'!$A:$A,B2)),0)),"Onbekend") | K2: =IFERROR(INDEX('🏷️ Categorieregels'!$C:$C,MATCH(TRUE,ISNUMBER(SEARCH('🏷️ Categorieregels'!$A:$A,B2)),0)),"")
A3: ='📥 CSV Import'!A6 | B3: ='📥 CSV Import'!B6 | C3: ='📥 CSV Import'!C6 | D3: ='📥 CSV Import'!D6 | E3: =IF(A3<>"",YEAR(A3),"") | F3: =IF(A3<>"",TEXT(A3,"YYYY-MM"),"") | G3: =IF(A3<>"",TEXT(A3,"MMMM YYYY"),"") | H3: =IF(C3>0,"Inkomsten",IF(C3<0,"Uitgaven","")) | I3: =IF(C3<>"",ABS(C3),"") | J3: =IFERROR(INDEX('🏷️ Categorieregels'!$B:$B,MATCH(TRUE,ISNUMBER(SEARCH('🏷️ Categorieregels'!$A:$A,B3)),0)),"Onbekend") | K3: =IFERROR(INDEX('🏷️ Categorieregels'!$C:$C,MATCH(TRUE,ISNUMBER(SEARCH('🏷️ Categorieregels'!$A:$A,B3)),0)),"")
A4: ='📥 CSV Import'!A7 | B4: ='📥 CSV Import'!B7 | C4: ='📥 CSV Import'!C7 | D4: ='📥 CSV Import'!D7 | E4: =IF(A4<>"",YEAR(A4),"") | F4: =IF(A4<>"",TEXT(A4,"YYYY-MM"),"") | G4: =IF(A4<>"",TEXT(A4,"MMMM YYYY"),"") | H4: =IF(C4>0,"Inkomsten",IF(C4<0,"Uitgaven","")) | I4: =IF(C4<>"",ABS(C4),"") | J4: =IFERROR(INDEX('🏷️ Categorieregels'!$B:$B,MATCH(TRUE,ISNUMBER(SEARCH('🏷️ Categorieregels'!$A:$A,B4)),0)),"Onbekend") | K4: =IFERROR(INDEX('🏷️ Categorieregels'!$C:$C,MATCH(TRUE,ISNUMBER(SEARCH('🏷️ Categorieregels'!$A:$A,B4)),0)),"")
A5: ='📥 CSV Import'!A8 | B5: ='📥 CSV Import'!B8 | C5: ='📥 CSV Import'!C8 | D5: ='📥 CSV Import'!D8 | E5: =IF(A5<>"",YEAR(A5),"") | F5: =IF(A5<>"",TEXT(A5,"YYYY-MM"),"") | G5: =IF(A5<>"",TEXT(A5,"MMMM YYYY"),"") | H5: =IF(C5>0,"Inkomsten",IF(C5<0,"Uitgaven","")) | I5: =IF(C5<>"",ABS(C5),"") | J5: =IFERROR(INDEX('🏷️ Categorieregels'!$B:$B,MATCH(TRUE,ISNUMBER(SEARCH('🏷️ Categorieregels'!$A:$A,B5)),0)),"Onbekend") | K5: =IFERROR(INDEX('🏷️ Categorieregels'!$C:$C,MATCH(TRUE,ISNUMBER(SEARCH('🏷️ Categorieregels'!$A:$A,B5)),0)),"")
A6: ='📥 CSV Import'!A9 | B6: ='📥 CSV Import'!B9 | C6: ='📥 CSV Import'!C9 | D6: ='📥 CSV Import'!D9 | E6: =IF(A6<>"",YEAR(A6),"") | F6: =IF(A6<>"",TEXT(A6,"YYYY-MM"),"") | G6: =IF(A6<>"",TEXT(A6,"MMMM YYYY"),"") | H6: =IF(C6>0,"Inkomsten",IF(C6<0,"Uitgaven","")) | I6: =IF(C6<>"",ABS(C6),"") | J6: =IFERROR(INDEX('🏷️ Categorieregels'!$B:$B,MATCH(TRUE,ISNUMBER(SEARCH('🏷️ Categorieregels'!$A:$A,B6)),0)),"Onbekend") | K6: =IFERROR(INDEX('🏷️ Categorieregels'!$C:$C,MATCH(TRUE,ISNUMBER(SEARCH('🏷️ Categorieregels'!$A:$A,B6)),0)),"")
A7: ='📥 CSV Import'!A10 | B7: ='📥 CSV Import'!B10 | C7: ='📥 CSV Import'!C10 | D7: ='📥 CSV Import'!D10 | E7: =IF(A7<>"",YEAR(A7),"") | F7: =IF(A7<>"",TEXT(A7,"YYYY-MM"),"") | G7: =IF(A7<>"",TEXT(A7,"MMMM YYYY"),"") | H7: =IF(C7>0,"Inkomsten",IF(C7<0,"Uitgaven","")) | I7: =IF(C7<>"",ABS(C7),"") | J7: =IFERROR(INDEX('🏷️ Categorieregels'!$B:$B,MATCH(TRUE,ISNUMBER(SEARCH('🏷️ Categorieregels'!$A:$A,B7)),0)),"Onbekend") | K7: =IFERROR(INDEX('🏷️ Categorieregels'!$C:$C,MATCH(TRUE,ISNUMBER(SEARCH('🏷️ Categorieregels'!$A:$A,B7)),0)),"")
A8: ='📥 CSV Import'!A11 | B8: ='📥 CSV Import'!B11 | C8: ='📥 CSV Import'!C11 | D8: ='📥 CSV Import'!D11 | E8: =IF(A8<>"",YEAR(A8),"") | F8: =IF(A8<>"",TEXT(A8,"YYYY-MM"),"") | G8: =IF(A8<>"",TEXT(A8,"MMMM YYYY"),"") | H8: =IF(C8>0,"Inkomsten",IF(C8<0,"Uitgaven","")) | I8: =IF(C8<>"",ABS(C8),"") | J8: =IFERROR(INDEX('🏷️ Categorieregels'!$B:$B,MATCH(TRUE,ISNUMBER(SEARCH('🏷️ Categorieregels'!$A:$A,B8)),0)),"Onbekend") | K8: =IFERROR(INDEX('🏷️ Categorieregels'!$C:$C,MATCH(TRUE,ISNUMBER(SEARCH('🏷️ Categorieregels'!$A:$A,B8)),0)),"")
A9: ='📥 CSV Import'!A12 | B9: ='📥 CSV Import'!B12 | C9: ='📥 CSV Import'!C12 | D9: ='📥 CSV Import'!D12 | E9: =IF(A9<>"",YEAR(A9),"") | F9: =IF(A9<>"",TEXT(A9,"YYYY-MM"),"") | G9: =IF(A9<>"",TEXT(A9,"MMMM YYYY"),"") | H9: =IF(C9>0,"Inkomsten",IF(C9<0,"Uitgaven","")) | I9: =IF(C9<>"",ABS(C9),"") | J9: =IFERROR(INDEX('🏷️ Categorieregels'!$B:$B,MATCH(TRUE,ISNUMBER(SEARCH('🏷️ Categorieregels'!$A:$A,B9)),0)),"Onbekend") | K9: =IFERROR(INDEX('🏷️ Categorieregels'!$C:$C,MATCH(TRUE,ISNUMBER(SEARCH('🏷️ Categorieregels'!$A:$A,B9)),0)),"")
A10: ='📥 CSV Import'!A13 | B10: ='📥 CSV Import'!B13 | C10: ='📥 CSV Import'!C13 | D10: ='📥 CSV Import'!D13 | E10: =IF(A10<>"",YEAR(A10),"") | F10: =IF(A10<>"",TEXT(A10,"YYYY-MM"),"") | G10: =IF(A10<>"",TEXT(A10,"MMMM YYYY"),"") | H10: =IF(C10>0,"Inkomsten",IF(C10<0,"Uitgaven","")) | I10: =IF(C10<>"",ABS(C10),"") | J10: =IFERROR(INDEX('🏷️ Categorieregels'!$B:$B,MATCH(TRUE,ISNUMBER(SEARCH('🏷️ Categorieregels'!$A:$A,B10)),0)),"Onbekend") | K10: =IFERROR(INDEX('🏷️ Categorieregels'!$C:$C,MATCH(TRUE,ISNUMBER(SEARCH('🏷️ Categorieregels'!$A:$A,B10)),0)),"")
A11: ='📥 CSV Import'!A14 | B11: ='📥 CSV Import'!B14 | C11: ='📥 CSV Import'!C14 | D11: ='📥 CSV Import'!D14 | E11: =IF(A11<>"",YEAR(A11),"") | F11: =IF(A11<>"",TEXT(A11,"YYYY-MM"),"") | G11: =IF(A11<>"",TEXT(A11,"MMMM YYYY"),"") | H11: =IF(C11>0,"Inkomsten",IF(C11<0,"Uitgaven","")) | I11: =IF(C11<>"",ABS(C11),"") | J11: =IFERROR(INDEX('🏷️ Categorieregels'!$B:$B,MATCH(TRUE,ISNUMBER(SEARCH('🏷️ Categorieregels'!$A:$A,B11)),0)),"Onbekend") | K11: =IFERROR(INDEX('🏷️ Categorieregels'!$C:$C,MATCH(TRUE,ISNUMBER(SEARCH('🏷️ Categorieregels'!$A:$A,B11)),0)),"")
A12: ='📥 CSV Import'!A15 | B12: ='📥 CSV Import'!B15 | C12: ='📥 CSV Import'!C15 | D12: ='📥 CSV Import'!D15 | E12: =IF(A12<>"",YEAR(A12),"") | F12: =IF(A12<>"",TEXT(A12,"YYYY-MM"),"") | G12: =IF(A12<>"",TEXT(A12,"MMMM YYYY"),"") | H12: =IF(C12>0,"Inkomsten",IF(C12<0,"Uitgaven","")) | I12: =IF(C12<>"",ABS(C12),"") | J12: =IFERROR(INDEX('🏷️ Categorieregels'!$B:$B,MATCH(TRUE,ISNUMBER(SEARCH('🏷️ Categorieregels'!$A:$A,B12)),0)),"Onbekend") | K12: =IFERROR(INDEX('🏷️ Categorieregels'!$C:$C,MATCH(TRUE,ISNUMBER(SEARCH('🏷️ Categorieregels'!$A:$A,B12)),0)),"")
A13: ='📥 CSV Import'!A16 | B13: ='📥 CSV Import'!B16 | C13: ='📥 CSV Import'!C16 | D13: ='📥 CSV Import'!D16 | E13: =IF(A13<>"",YEAR(A13),"") | F13: =IF(A13<>"",TEXT(A13,"YYYY-MM"),"") | G13: =IF(A13<>"",TEXT(A13,"MMMM YYYY"),"") | H13: =IF(C13>0,"Inkomsten",IF(C13<0,"Uitgaven","")) | I13: =IF(C13<>"",ABS(C13),"") | J13: =IFERROR(INDEX('🏷️ Categorieregels'!$B:$B,MATCH(TRUE,ISNUMBER(SEARCH('🏷️ Categorieregels'!$A:$A,B13)),0)),"Onbekend") | K13: =IFERROR(INDEX('🏷️ Categorieregels'!$C:$C,MATCH(TRUE,ISNUMBER(SEARCH('🏷️ Categorieregels'!$A:$A,B13)),0)),"")
... A101: ='📥 CSV Import'!A104 | B101: ='📥 CSV Import'!B104 | C101: ='📥 CSV Import'!C104 | D101: ='📥 CSV Import'!D104 | E101: =IF(A101<>"",YEAR(A101),"") | F101: =IF(A101<>"",TEXT(A101,"YYYY-MM"),"") | G101: =IF(A101<>"",TEXT(A101,"MMMM YYYY"),"") | H101: =IF(C101>0,"Inkomsten",IF(C101<0,"Uitgaven","")) | I101: =IF(C101<>"",ABS(C101),"") | J101: =IFERROR(INDEX('🏷️ Categorieregels'!$B:$B,MATCH(TRUE,ISNUMBER(SEARCH('🏷️ Categorieregels'!$A:$A,B101)),0)),"Onbekend") | K101: =IFERROR(INDEX('🏷️ Categorieregels'!$C:$C,MATCH(TRUE,ISNUMBER(SEARCH('🏷️ Categorieregels'!$A:$A,B101)),0)),"")

Sheet 📊 Dashboard
A1: 📊 DASHBOARD
A3: OVERZICHT
A5: Totaal Inkomsten: | B5: =SUMIF('✅ Data Verwerkt'!H:H,"Inkomsten",'✅ Data Verwerkt'!I:I)
A6: Totaal Uitgaven: | B6: =SUMIF('✅ Data Verwerkt'!H:H,"Uitgaven",'✅ Data Verwerkt'!I:I)
A7: Saldo: | B7: =B5-B6
A9: Aantal Transacties: | B9: =COUNTA('✅ Data Verwerkt'!A:A)-1
A11: 💡 TIP: Maak een PivotTable voor gedetailleerde analyses
A12: Selecteer data in 'Data Verwerkt' → Insert → PivotTable
